Workbook

Sheet naming pools
B1: Europe | C1: Complexity | D1: Importance | G1: Name Census | H1: surnames | I1: firstnames
A2: =TRIM(B2) -> Iceland | B2: Iceland | C2: T4 | D2: G2 | E2: Iceland | F2: Small market, decent football culture, one pool enough | G2: =VLOOKUP($A2,NameCensus!$C$2:$E$140,1,FALSE) -> Iceland | H2: =VLOOKUP($A2,NameCensus!$C$2:$E$140,2,FALSE) -> 498 | I2: =VLOOKUP($A2,NameCensus!$C$2:$E$140,3,FALSE) -> 2.337
A3: =TRIM(B3) -> Norway | B3: Norway | C3: T4 | D3: G2 | E3: Norway | F3: Strong monetization potential, one pool enough | G3: =VLOOKUP($A3,NameCensus!$C$2:$E$140,1,FALSE) -> Norway | H3: =VLOOKUP($A3,NameCensus!$C$2:$E$140,2,FALSE) -> 4.81 | I3: =VLOOKUP($A3,NameCensus!$C$2:$E$140,3,FALSE) -> 11.421
A4: =TRIM(B4) -> Sweden | B4: Sweden | C4: T4 | D4: G2 | E4: Sweden | F4: Strong football interest + monetization potential | G4: =VLOOKUP($A4,NameCensus!$C$2:$E$140,1,FALSE) -> Sweden | H4: =VLOOKUP($A4,NameCensus!$C$2:$E$140,2,FALSE) -> 6.234 | I4: =VLOOKUP($A4,NameCensus!$C$2:$E$140,3,FALSE) -> 12.705
A5: =TRIM(B5) -> Denmark | B5: Denmark | C5: T4 | D5: G2 | E5: Denmark | F5: Strong football interest + monetization potential | G5: =VLOOKUP($A5,NameCensus!$C$2:$E$140,1,FALSE) -> Denmark | H5: =VLOOKUP($A5,NameCensus!$C$2:$E$140,2,FALSE) -> 3.745 | I5: =VLOOKUP($A5,NameCensus!$C$2:$E$140,3,FALSE) -> 8.827
A6: =TRIM(B6) -> Finland | B6: Finland | C6: T3 | D6: G2 | E6: Finland; Finland Swedish | F6: Good market, moderate split worth keeping | G6: =VLOOKUP($A6,NameCensus!$C$2:$E$140,1,FALSE) -> Finland | H6: =VLOOKUP($A6,NameCensus!$C$2:$E$140,2,FALSE) -> 4.426 | I6: =VLOOKUP($A6,NameCensus!$C$2:$E$140,3,FALSE) -> 8.371
A7: =TRIM(B7) -> England | B7: England | C7: T4 | D7: G1 | E7: England | F7: Flagship football market | G7: =VLOOKUP($A7,NameCensus!$C$2:$E$140,1,FALSE) -> #N/A | H7: =VLOOKUP($A7,NameCensus!$C$2:$E$140,2,FALSE) -> #N/A | I7: =VLOOKUP($A7,NameCensus!$C$2:$E$140,3,FALSE) -> #N/A
A8: =TRIM(B8) -> Scotland | B8: Scotland | C8: T4 | D8: G2 | E8: Scotland | F8: Strong football culture, one pool enough | G8: =VLOOKUP($A8,NameCensus!$C$2:$E$140,1,FALSE) -> #N/A | H8: =VLOOKUP($A8,NameCensus!$C$2:$E$140,2,FALSE) -> #N/A | I8: =VLOOKUP($A8,NameCensus!$C$2:$E$140,3,FALSE) -> #N/A | J8: ONLY as UK
A9: =TRIM(B9) -> Wales | B9: Wales | C9: T4 | D9: G2 | E9: Wales | F9: Strong football culture, one pool enough | G9: =VLOOKUP($A9,NameCensus!$C$2:$E$140,1,FALSE) -> #N/A | H9: =VLOOKUP($A9,NameCensus!$C$2:$E$140,2,FALSE) -> #N/A | I9: =VLOOKUP($A9,NameCensus!$C$2:$E$140,3,FALSE) -> #N/A
A10: =TRIM(B10) -> Northern Ireland | B10: Northern Ireland | C10: T3 | D10: G2 | E10: Northern Ireland | F10: Useful regional distinction | G10: =VLOOKUP($A10,NameCensus!$C$2:$E$140,1,FALSE) -> #N/A | H10: =VLOOKUP($A10,NameCensus!$C$2:$E$140,2,FALSE) -> #N/A | I10: =VLOOKUP($A10,NameCensus!$C$2:$E$140,3,FALSE) -> #N/A
A11: =TRIM(B11) -> Ireland | B11: Ireland | C11: T4 | D11: G2 | E11: Ireland | F11: Strong monetization and football relevance | G11: =VLOOKUP($A11,NameCensus!$C$2:$E$140,1,FALSE) -> Ireland | H11: =VLOOKUP($A11,NameCensus!$C$2:$E$140,2,FALSE) -> 6.744 | I11: =VLOOKUP($A11,NameCensus!$C$2:$E$140,3,FALSE) -> 13.044
A12: =TRIM(B12) -> France | B12: France | C12: T4 | D12: G1 | E12: France | F12: Flagship football market | G12: =VLOOKUP($A12,NameCensus!$C$2:$E$140,1,FALSE) -> France | H12: =VLOOKUP($A12,NameCensus!$C$2:$E$140,2,FALSE) -> 41.459 | I12: =VLOOKUP($A12,NameCensus!$C$2:$E$140,3,FALSE) -> 38.788
A13: =TRIM(B13) -> Belgium | B13: Belgium | C13: T3 | D13: G2 | E13: Belgium Dutch; Belgium French | F13: Split worth it and football relevance is high | G13: =VLOOKUP($A13,NameCensus!$C$2:$E$140,1,FALSE) -> Belgium | H13: =VLOOKUP($A13,NameCensus!$C$2:$E$140,2,FALSE) -> 14.538 | I13: =VLOOKUP($A13,NameCensus!$C$2:$E$140,3,FALSE) -> 22.416
A14: =TRIM(B14) -> Netherlands | B14: Netherlands | C14: T4 | D14: G1 | E14: Netherlands | F14: Flagship football culture + strong market | G14: =VLOOKUP($A14,NameCensus!$C$2:$E$140,1,FALSE) -> Netherlands | H14: =VLOOKUP($A14,NameCensus!$C$2:$E$140,2,FALSE) -> 34.213 | I14: =VLOOKUP($A14,NameCensus!$C$2:$E$140,3,FALSE) -> 31.073
A15: =TRIM(B15) -> Luxembourg | B15: Luxembourg | C15: T4 | D15: G3 | E15: Luxembourg Local | F15: Small but high monetization potential | G15: =VLOOKUP($A15,NameCensus!$C$2:$E$140,1,FALSE) -> Luxembourg | H15: =VLOOKUP($A15,NameCensus!$C$2:$E$140,2,FALSE) -> 1.889 | I15: =VLOOKUP($A15,NameCensus!$C$2:$E$140,3,FALSE) -> 6.174
A16: =TRIM(B16) -> Germany | B16: Germany | C16: T4 | D16: G1 | E16: Germany | F16: Flagship football market | G16: =VLOOKUP($A16,NameCensus!$C$2:$E$140,1,FALSE) -> Germany | H16: =VLOOKUP($A16,NameCensus!$C$2:$E$140,2,FALSE) -> 37.01 | I16: =VLOOKUP($A16,NameCensus!$C$2:$E$140,3,FALSE) -> 35.016
A17: =TRIM(B17) -> Austria | B17: Austria | C17: T4 | D17: G2 | E17: Austria | F17: Good market, one pool enough | G17: =VLOOKUP($A17,NameCensus!$C$2:$E$140,1,FALSE) -> Austria | H17: =VLOOKUP($A17,NameCensus!$C$2:$E$140,2,FALSE) -> 5.242 | I17: =VLOOKUP($A17,NameCensus!$C$2:$E$140,3,FALSE) -> 10.238
A18: =TRIM(B18) -> Switzerland | B18: Switzerland | C18: T3 | D18: G1 | E18: Swiss German; Swiss French; Swiss Italian | F18: High-value market and split is worth it | G18: =VLOOKUP($A18,NameCensus!$C$2:$E$140,1,FALSE) -> Switzerland | H18: =VLOOKUP($A18,NameCensus!$C$2:$E$140,2,FALSE) -> 6.085 | I18: =VLOOKUP($A18,NameCensus!$C$2:$E$140,3,FALSE) -> 13.547
A19: =TRIM(B19) -> Spain | B19: Spain | C19: T4 | D19: G1 | E19: Spain | F19: Flagship football market | G19: =VLOOKUP($A19,NameCensus!$C$2:$E$140,1,FALSE) -> Spain | H19: =VLOOKUP($A19,NameCensus!$C$2:$E$140,2,FALSE) -> 32.21 | I19: =VLOOKUP($A19,NameCensus!$C$2:$E$140,3,FALSE) -> 36.696
A20: =TRIM(B20) -> Andorra | B20: Andorra | C20: T4 | D20: G4 | E20: Andorra Local | F20: Low priority micro-market | G20: =VLOOKUP($A20,NameCensus!$C$2:$E$140,1,FALSE) -> #N/A | H20: =VLOOKUP($A20,NameCensus!$C$2:$E$140,2,FALSE) -> #N/A | I20: =VLOOKUP($A20,NameCensus!$C$2:$E$140,3,FALSE) -> #N/A | J20: spain+france | K20: Catalan space; Spanish/Catalan-first usually works better than French-only
A21: =TRIM(B21) -> Portugal | B21: Portugal | C21: T4 | D21: G1 | E21: Portugal | F21: Strong football interest, good global relevance | G21: =VLOOKUP($A21,NameCensus!$C$2:$E$140,1,FALSE) -> Portugal | H21: =VLOOKUP($A21,NameCensus!$C$2:$E$140,2,FALSE) -> 2.752 | I21: =VLOOKUP($A21,NameCensus!$C$2:$E$140,3,FALSE) -> 9.18
A22: =TRIM(B22) -> Italy | B22: Italy | C22: T4 | D22: G1 | E22: Italy | F22: Flagship football market | G22: =VLOOKUP($A22,NameCensus!$C$2:$E$140,1,FALSE) -> Italy | H22: =VLOOKUP($A22,NameCensus!$C$2:$E$140,2,FALSE) -> 32.816 | I22: =VLOOKUP($A22,NameCensus!$C$2:$E$140,3,FALSE) -> 23.773
A23: =TRIM(B23) -> San Marino | B23: San Marino | C23: T4 | D23: G4 | E23: San Marino Local | F23: Micro-market, can stay simple | G23: =VLOOKUP($A23,NameCensus!$C$2:$E$140,1,FALSE) -> #N/A | H23: =VLOOKUP($A23,NameCensus!$C$2:$E$140,2,FALSE) -> #N/A | I23: =VLOOKUP($A23,NameCensus!$C$2:$E$140,3,FALSE) -> #N/A | J23: Italy
A24: =TRIM(B24) -> Malta | B24: Malta | C24: T3 | D24: G3 | E24: Malta | F24: Small market but distinct enough to keep | G24: =VLOOKUP($A24,NameCensus!$C$2:$E$140,1,FALSE) -> Malta | H24: =VLOOKUP($A24,NameCensus!$C$2:$E$140,2,FALSE) -> 256 | I24: =VLOOKUP($A24,NameCensus!$C$2:$E$140,3,FALSE) -> 2.263
A25: =TRIM(B25) -> Poland | B25: Poland | C25: T4 | D25: G2 | E25: Poland | F25: Large football-relevant market | G25: =VLOOKUP($A25,NameCensus!$C$2:$E$140,1,FALSE) -> Poland | H25: =VLOOKUP($A25,NameCensus!$C$2:$E$140,2,FALSE) -> 11.136 | I25: =VLOOKUP($A25,NameCensus!$C$2:$E$140,3,FALSE) -> 7.021
A26: =TRIM(B26) -> Czech Republic | B26: Czech Republic | C26: T4 | D26: G2 | E26: Czech Republic | F26: Good football market, one pool enough | G26: =VLOOKUP($A26,NameCensus!$C$2:$E$140,1,FALSE) -> Czech Republic | H26: =VLOOKUP($A26,NameCensus!$C$2:$E$140,2,FALSE) -> 6.331 | I26: =VLOOKUP($A26,NameCensus!$C$2:$E$140,3,FALSE) -> 8.153
A27: =TRIM(B27) -> Slovakia | B27: Slovakia | C27: T4 | D27: G2 | E27: Slovakia | F27: Medium priority | G27: =VLOOKUP($A27,NameCensus!$C$2:$E$140,1,FALSE) -> Slovakia | H27: =VLOOKUP($A27,NameCensus!$C$2:$E$140,2,FALSE) -> 2.782 | I27: =VLOOKUP($A27,NameCensus!$C$2:$E$140,3,FALSE) -> 3.51
A28: =TRIM(B28) -> Hungary | B28: Hungary | C28: T4 | D28: G2 | E28: Hungary | F28: Good football relevance, one pool enough | G28: =VLOOKUP($A28,NameCensus!$C$2:$E$140,1,FALSE) -> Hungary | H28: =VLOOKUP($A28,NameCensus!$C$2:$E$140,2,FALSE) -> 2.545 | I28: =VLOOKUP($A28,NameCensus!$C$2:$E$140,3,FALSE) -> 7.619
A29: =TRIM(B29) -> Romania | B29: Romania | C29: T4 | D29: G2 | E29: Romania | F29: Large enough and football-relevant | G29: =VLOOKUP($A29,NameCensus!$C$2:$E$140,1,FALSE) -> Romania | H29: =VLOOKUP($A29,NameCensus!$C$2:$E$140,2,FALSE) -> 4.13 | I29: =VLOOKUP($A29,NameCensus!$C$2:$E$140,3,FALSE) -> 9.419
A30: =TRIM(B30) -> Moldova | B30: Moldova | C30: T3 | D30: G4 | E30: Moldova | F30: Keep separate if modeled, but lower priority | G30: =VLOOKUP($A30,NameCensus!$C$2:$E$140,1,FALSE) -> Moldova | H30: =VLOOKUP($A30,NameCensus!$C$2:$E$140,2,FALSE) -> 286 | I30: =VLOOKUP($A30,NameCensus!$C$2:$E$140,3,FALSE) -> 1.722
A31: =TRIM(B31) -> Slovenia | B31: Slovenia | C31: T4 | D31: G2 | E31: Slovenia | F31: Medium priority | G31: =VLOOKUP($A31,NameCensus!$C$2:$E$140,1,FALSE) -> Slovenia | H31: =VLOOKUP($A31,NameCensus!$C$2:$E$140,2,FALSE) -> 1.487 | I31: =VLOOKUP($A31,NameCensus!$C$2:$E$140,3,FALSE) -> 3.754
A32: =TRIM(B32) -> Croatia | B32: Croatia | C32: T4 | D32: G2 | E32: Croatia | F32: Small market but high football salience | G32: =VLOOKUP($A32,NameCensus!$C$2:$E$140,1,FALSE) -> Croatia | H32: =VLOOKUP($A32,NameCensus!$C$2:$E$140,2,FALSE) -> 1.951 | I32: =VLOOKUP($A32,NameCensus!$C$2:$E$140,3,FALSE) -> 3.929
A33: =TRIM(B33) -> Bosnia and Herzegovina | B33: Bosnia and Herzegovina | C33: T3 | D33: G2 | E33: Bosnia and Herzegovina | F33: Medium priority, one V1 pool | G33: =VLOOKUP($A33,NameCensus!$C$2:$E$140,1,FALSE) -> Bosnia and Herzegovina | H33: =VLOOKUP($A33,NameCensus!$C$2:$E$140,2,FALSE) -> 1.417 | I33: =VLOOKUP($A33,NameCensus!$C$2:$E$140,3,FALSE) -> 5.021
A34: =TRIM(B34) -> Serbia | B34: Serbia | C34: T4 | D34: G2 | E34: Serbia | F34: Strong football salience | G34: =VLOOKUP($A34,NameCensus!$C$2:$E$140,1,FALSE) -> Serbia | H34: =VLOOKUP($A34,NameCensus!$C$2:$E$140,2,FALSE) -> 2.322 | I34: =VLOOKUP($A34,NameCensus!$C$2:$E$140,3,FALSE) -> 4.261
A35: =TRIM(B35) -> Montenegro | B35: Montenegro | C35: T3 | D35: G3 | E35: Montenegro | F35: Lower priority, keep simple | G35: =VLOOKUP($A35,NameCensus!$C$2:$E$140,1,FALSE) -> #N/A | H35: =VLOOKUP($A35,NameCensus!$C$2:$E$140,2,FALSE) -> #N/A | I35: =VLOOKUP($A35,NameCensus!$C$2:$E$140,3,FALSE) -> #N/A | J35: Serbia+ Croatia +Bonsia | K35: Serbia-first usually enough; blend helps
A36: =TRIM(B36) -> Kosovo | B36: Kosovo | C36: T3 | D36: G4 | E36: Kosovo | F36: Lower priority, separate if modeled | G36: =VLOOKUP($A36,NameCensus!$C$2:$E$140,1,FALSE) -> Kosovo | H36: =VLOOKUP($A36,NameCensus!$C$2:$E$140,2,FALSE) -> 1.047 | I36: =VLOOKUP($A36,NameCensus!$C$2:$E$140,3,FALSE) -> 4.918
A37: =TRIM(B37) -> Albania | B37: Albania | C37: T4 | D37: G3 | E37: Albania | F37: Medium priority | G37: =VLOOKUP($A37,NameCensus!$C$2:$E$140,1,FALSE) -> Albania | H37: =VLOOKUP($A37,NameCensus!$C$2:$E$140,2,FALSE) -> 1.202 | I37: =VLOOKUP($A37,NameCensus!$C$2:$E$140,3,FALSE) -> 4.058
A38: =TRIM(B38) -> North Macedonia | B38: North Macedonia | C38: T3 | D38: G4 | E38: North Macedonia | F38: Lower priority, separate if modeled | G38: =VLOOKUP($A38,NameCensus!$C$2:$E$140,1,FALSE) -> #N/A | H38: =VLOOKUP($A38,NameCensus!$C$2:$E$140,2,FALSE) -> #N/A | I38: =VLOOKUP($A38,NameCensus!$C$2:$E$140,3,FALSE) -> #N/A | J38: Available as Macedonia?
A39: =TRIM(B39) -> Bulgaria | B39: Bulgaria | C39: T4 | D39: G2 | E39: Bulgaria | F39: Medium priority | G39: =VLOOKUP($A39,NameCensus!$C$2:$E$140,1,FALSE) -> Bulgaria | H39: =VLOOKUP($A39,NameCensus!$C$2:$E$140,2,FALSE) -> 2.746 | I39: =VLOOKUP($A39,NameCensus!$C$2:$E$140,3,FALSE) -> 7.628
A40: =TRIM(B40) -> Greece | B40: Greece | C40: T4 | D40: G2 | E40: Greece | F40: Good football market | G40: =VLOOKUP($A40,NameCensus!$C$2:$E$140,1,FALSE) -> Greece | H40: =VLOOKUP($A40,NameCensus!$C$2:$E$140,2,FALSE) -> 3.041 | I40: =VLOOKUP($A40,NameCensus!$C$2:$E$140,3,FALSE) -> 6.818
...

Sheet Sheet14
A3: Sum of percent | B3: Column Labels
A4: Row Labels | B4: T1 | C4: T2 | D4: Grand Total
A5: AfroBrazil | B5: 22 | C5: 4 | D5: 26
A6: RedHair | B6: 62 | D6: 62
A7: IndiaBengali | B7: 12 | C7: 70 | D7: 82
A8: IndiaPunjab | B8: 26 | C8: 66 | D8: 92
A9: SEA Vietic | B9: 98 | D9: 98
A10: Japan | B10: 102 | C10: 2 | D10: 104
A11: IndieSriLanka | B11: 2 | C11: 106 | D11: 108
A12: Korea | B12: 100 | C12: 10 | D12: 110
A13: Brazil Pardo | B13: 90 | C13: 30 | D13: 120
A14: Philipines | B14: 113 | C14: 10 | D14: 123
A15: MesoAmericaIndigenous | B15: 61 | C15: 73 | D15: 134
A16: Finno | B16: 133 | C16: 6 | D16: 139
A17: AsiaCentralTajik | B17: 28 | C17: 122 | D17: 150
A18: Egypt | B18: 115 | C18: 41 | D18: 156
A19: IndiaGangetic | B19: 38 | C19: 170 | D19: 208
A20: IndiaSouth | B20: 146 | C20: 71 | D20: 217
A21: Scandinavia | B21: 243 | D21: 243
A22: Polynesia | B22: 51 | C22: 206 | D22: 257
A23: Caucasus | B23: 107 | C23: 153 | D23: 260
A24: Persia | B24: 157 | C24: 117 | D24: 274
A25: Andean | B25: 263 | C25: 15 | D25: 278
A26: SEA insular | B26: 263 | C26: 24 | D26: 287
A27: Anatolian | B27: 195 | C27: 96 | D27: 291
A28: SouthernCone | B28: 327 | D28: 327
A29: EuroIberian | B29: 194 | C29: 142 | D29: 336
A30: EuroNorth | B30: 326 | C30: 15 | D30: 341
A31: AsiaCentralUzbek | B31: 140 | C31: 201 | D31: 341
A32: SEA Mekong | B32: 111 | C32: 254 | D32: 365
A33: EuroItaMed | B33: 168 | C33: 206 | D33: 374
A34: Melanesia | B34: 56 | C34: 340 | D34: 396
A35: SouthAmericaNorth | B35: 237 | C35: 165 | D35: 402
A36: AfricaHorn | B36: 53 | C36: 391 | D36: 444
A37: AfricaSahelia | B37: 92 | C37: 371 | D37: 463
A38: China | B38: 302 | C38: 180 | D38: 482
A39: AfricaNorth | B39: 364 | C39: 158 | D39: 522
A40: MesoAmericaMestizo | B40: 200 | C40: 347 | D40: 547
... A52: Grand Total | B52: 9894 | C52: 8498 | D52: 18392

Sheet Sheet2
A3: Row Labels | B3: Count of VisualBucket
A4: Afghanistan | B4: 10
A5: Anatolian | B5: 1
A6: ArabPeninsula | B6: 1
A7: AsiaCentralTajik | B7: 1
A8: AsiaCentralUzbek | B8: 1
A9: China | B9: 1
A10: IndiaGangetic | B10: 1
A11: IndiaPunjab | B11: 1
A12: Levant | B12: 1
A13: Persia | B13: 2
A14: Albania | B14: 7
A15: AfricaWest | B15: 1
... A1403: AfricaWest | B1403: 1
A1404: (blank)
A1405: (blank)
A1406: Grand Total | B1406: 1272

Sheet Sheet1
A1: Country | B1: VisualBucket
A2: Iceland | B2: Scandinavia
A3: Iceland | B3: EuroNorth
A4: Iceland | B4: RedHair
A5: Norway | B5: Scandinavia
A6: Norway | B6: EuroNorth
A7: Norway | B7: Anatolian
A8: Norway | B8: Levant
A9: Norway | B9: Persia
A10: Norway | B10: AfricaHorn
A11: Norway | B11: RedHair
A12: Sweden | B12: Scandinavia
... A1273: Marshall Islands | B1273: Melanesia

Sheet TopMarkets
A1: Region | B1: Country | C1: VisualBucket | D1: percent | E1: naming pool | F1: Persona | G1: naming split
A2: UEFA | B2: Iceland | C2: Scandinavia | D2: 58 | E2: Iceland 1.00 | F2: FULL_HERITAGE | G2: HERITAGE_HERITAGE 0.95, NATION_HERITAGE 0.03, NATION_NATION 0.02, HERITAGE_NATION 0.00
A3: UEFA | B3: Iceland | C3: EuroNorth | D3: 38 | E3: Iceland 1.00 | F3: FULL_HERITAGE | G3: HERITAGE_HERITAGE 0.95, NATION_HERITAGE 0.03, NATION_NATION 0.02, HERITAGE_NATION 0.00
A4: UEFA | B4: Iceland | C4: RedHair | D4: 4 | E4: Iceland 1.00 | F4: FULL_HERITAGE | G4: HERITAGE_HERITAGE 0.95, NATION_HERITAGE 0.03, NATION_NATION 0.02, HERITAGE_NATION 0.00
A5: UEFA | B5: Norway | C5: Scandinavia | D5: 56 | E5: Norway 0.88, Denmark 0.07, Sweden 0.05 | F5: FULL_HERITAGE | G5: HERITAGE_HERITAGE 0.95, NATION_HERITAGE 0.03, NATION_NATION 0.02, HERITAGE_NATION 0.00
A6: UEFA | B6: Norway | C6: EuroNorth | D6: 29 | E6: Norway 0.88, Denmark 0.07, Sweden 0.05 | F6: FULL_HERITAGE | G6: HERITAGE_HERITAGE 0.95, NATION_HERITAGE 0.03, NATION_NATION 0.02, HERITAGE_NATION 0.00
A7: UEFA | B7: Norway | C7: Anatolian | D7: 3 | E7: Turkey 0.85, Norway 0.15 | F7: HERITAGE_BALANCED | G7: HERITAGE_HERITAGE 0.53, NATION_HERITAGE 0.42, NATION_NATION 0.04, HERITAGE_NATION 0.01
A8: UEFA | B8: Norway | C8: Levant | D8: 5 | E8: Iraq 0.45, Syria 0.45, Lebanon 0.10 | F8: HERITAGE_BALANCED | G8: HERITAGE_HERITAGE 0.53, NATION_HERITAGE 0.42, NATION_NATION 0.04, HERITAGE_NATION 0.01
A9: UEFA | B9: Norway | C9: Persia | D9: 2 | E9: Iran 0.90, Norway 0.10 | F9: HERITAGE_BALANCED | G9: HERITAGE_HERITAGE 0.53, NATION_HERITAGE 0.42, NATION_NATION 0.04, HERITAGE_NATION 0.01
A10: UEFA | B10: Norway | C10: AfricaHorn | D10: 2 | E10: Somalia 0.70, Ethiopia 0.30 | F10: HERITAGE_HEAVY | G10: HERITAGE_HERITAGE 0.60, NATION_HERITAGE 0.35, NATION_NATION 0.04, HERITAGE_NATION 0.01
A11: UEFA | B11: Norway | C11: RedHair | D11: 3 | E11: Norway 1.00 | F11: FULL_HERITAGE | G11: HERITAGE_HERITAGE 0.95, NATION_HERITAGE 0.03, NATION_NATION 0.02, HERITAGE_NATION 0.00
A12: UEFA | B12: Sweden | C12: Scandinavia | D12: 48 | E12: Sweden 0.92, Norway 0.08 | F12: FULL_HERITAGE | G12: HERITAGE_HERITAGE 0.95, NATION_HERITAGE 0.03, NATION_NATION 0.02, HERITAGE_NATION 0.00
A13: UEFA | B13: Sweden | C13: EuroNorth | D13: 24 | E13: Sweden 0.92, Norway 0.08 | F13: FULL_HERITAGE | G13: HERITAGE_HERITAGE 0.95, NATION_HERITAGE 0.03, NATION_NATION 0.02, HERITAGE_NATION 0.00
... A1186: OFC | B1186: Marshall Islands | C1186: Melanesia | D1186: 10 | E1186: Polynesia 0.60, Melanesia 0.40 | F1186: HERITAGE_HEAVY | G1186: HERITAGE_HERITAGE 0.60, NATION_HERITAGE 0.35, NATION_NATION 0.04, HERITAGE_NATION 0.01

Sheet FullNamingPoolList
A1: Country | B1: countrycode | C1: Country | D1: Surnames | E1: FirstNames
A2: Afghanistan | B2: AF | C2: Afghanistan | D2: 2.107 | E2: 8.414
A3: Albania | B3: AL | C3: Albania | D3: 1.202 | E3: 4.058 | J3: Extra nations
A4: Algeria | B4: DZ | C4: Algeria | D4: 3.426 | E4: 7.185
A5: Angola | B5: AO | C5: Angola | D5: 793 | E5: 4.996 | J5: Faroe Islands
A6: Argentina | B6: AR | C6: Argentina | D6: 16.343 | E6: 18.962 | J6: Puerto Rico
A7: Armenia | B7: AM | C7: Armenia | D7: 352 | E7: 1.901 | J7: Gibraltar
A8: Australia | B8: AU | C8: Australia | D8: 16.841 | E8: 25.909
A9: Austria | B9: AT | C9: Austria | D9: 5.242 | E9: 10.238 | J9: Guam
A10: Azerbaijan | B10: AZ | C10: Azerbaijan | D10: 608 | E10: 3.003 | J10: American Samoa
A11: Bahamas | B11: BS | C11: Bahamas | D11: 498 | E11: 2.978 | J11: British Virgin Islands
A12: Bahrain | B12: BH | C12: Bahrain | D12: 394 | E12: 2.066 | J12: US Virgin Islands
A13: Bangladesh | B13: BD | C13: Bangladesh | D13: 2.432 | E13: 11.283 | J13: Cayman Islands
A14: Belarus | B14: BY | C14: Belarus | D14: 1.924 | E14: 3.352 | J14: Bermuda
A15: Belgium | B15: BE | C15: Belgium | D15: 14.538 | E15: 22.416 | J15: Cook Islands
A16: Belize | B16: BZ | C16: Belize | D16: 526 | E16: 2.803 | J16: Tahiti
A17: Benin | B17: BJ | C17: Benin | D17: 372 | E17: 3.384
A18: Bermuda | B18: BM | C18: Bermuda | D18: 1.854 | E18: 4.634
A19: Bolivia | B19: BO | C19: Bolivia | D19: 1.238 | E19: 5.452
A20: Bosnia and Herzegovina | B20: BA | C20: Bosnia and Herzegovina | D20: 1.417 | E20: 5.021
A21: Brazil | B21: BR | C21: Brazil | D21: 23.007 | E21: 44.957
A22: Bulgaria | B22: BG | C22: Bulgaria | D22: 2.746 | E22: 7.628
A23: Burkina Faso | B23: BF | C23: Burkina Faso | D23: 703 | E23: 5.3
A24: Cameroon | B24: CM | C24: Cameroon | D24: 2.478 | E24: 8.608
A25: Canada | B25: CA | C25: Canada | D25: 28.007 | E25: 36.463
A26: Cape Verde | B26: CV | C26: Cape Verde | D26: 458 | E26: 3.283
A27: Chile | B27: CL | C27: Chile | D27: 4.275 | E27: 11.293
A28: China | B28: CN | C28: China | D28: 1.89 | E28: 13.108
... A140: Zimbabwe | B140: ZW | C140: Zimbabwe | D140: 914 | E140: 3.828
A141: DR Congo | F141: Same as Congo in name Census
A142: North Macedonia | F142: same as Macedonia
A143: Korea | F143: same as South Korea
A144: UAE | F144: United Arab Emirates
A145: Myanmar | F145: same as Myanmar Burma
A146: England | F146: split
A147: Wales | F147: split
A148: Northern Ireland | F148: split
A149: Scotland | F149: split
A150: swiss german | F150: split
A151: swiss french | F151: split
...

Sheet Missing Naming pools
A1: Country | B1: Best fallback pool(s) | C1: Coverage quality | D1: Note
A2: Andorra | B2: Spain + France | C2: Good | D2: Catalan space; Spanish/Catalan-first usually works better than French-only
A3: Aruba | B3: Netherlands + Caribbean + Venezuela/LatAm blend | C3: Good | D3: Dutch alone too narrow
A4: Barbados | B4: AfroCaribbean / Jamaica / Trinidad-type Caribbean pool | C4: Good | D4: Anglophone Caribbean pattern
A5: Bhutan | B5: Nepal + Tibet/Himalayan-style custom enrich | C5: Weak | D5: South Asian fallback alone is not ideal
A6: Botswana | B6: South Africa | C6: Good | D6: Southern African fallback works well
A7: Burundi | B7: Rwanda + Tanzania | C7: Good | D7: Rwanda-first usually works
A8: Cambodia | B8: Thailand + Vietnam (light) + Khmer enrich | C8: Medium | D8: Thailand-alone is too wrong
A9: Central African Republic | B9: Cameroon + Congo + Chad | C9: Medium | D9: Needs Central African blend
A10: Chad | B10: Niger + Sudan + CAR + Cameroon | C10: Medium | D10: Mixed Sahel/Central fallback
A11: Curaçao | B11: Netherlands + Caribbean | C11: Good | D11: Dutch-Caribbean blend works
A12: Djibouti | B12: Somalia + Ethiopia + Arab enrich | C12: Medium | D12: Needs Horn/Arab blend
... A48: Yemen | B48: Saudi / ArabPeninsula | C48: Good | D48: Good fallback, but Yemeni specifics would improve it

Sheet NameCensus
A1: Country | B1: countrycode | C1: Country | D1: Surnames | E1: FirstNames
A2: Afghanistan | B2: AF | C2: Afghanistan | D2: 2.107 | E2: 8.414
A3: Albania | B3: AL | C3: Albania | D3: 1.202 | E3: 4.058
A4: Algeria | B4: DZ | C4: Algeria | D4: 3.426 | E4: 7.185
A5: Angola | B5: AO | C5: Angola | D5: 793 | E5: 4.996
A6: Argentina | B6: AR | C6: Argentina | D6: 16.343 | E6: 18.962
A7: Armenia | B7: AM | C7: Armenia | D7: 352 | E7: 1.901
A8: Australia | B8: AU | C8: Australia | D8: 16.841 | E8: 25.909
A9: Austria | B9: AT | C9: Austria | D9: 5.242 | E9: 10.238
A10: Azerbaijan | B10: AZ | C10: Azerbaijan | D10: 608 | E10: 3.003
A11: Bahamas | B11: BS | C11: Bahamas | D11: 498 | E11: 2.978
A12: Bahrain | B12: BH | C12: Bahrain | D12: 394 | E12: 2.066
A13: Bangladesh | B13: BD | C13: Bangladesh | D13: 2.432 | E13: 11.283
... A140: Zimbabwe | B140: ZW | C140: Zimbabwe | D140: 914 | E140: 3.828

Sheet heritage_europe
A2: Country | B2: VisualBucket | C2: percent | D2: naming pool | E2: naming split | F2: notes
A3: Iceland | B3: Scandinavia | C3: 58 | D3: Iceland 1.00 | E3: LOCAL_LOCAL 0.95, DOUBLE_SURNAME_LOCAL_LOCAL 0.03, COMPOUND_GIVEN_LOCAL_LOCAL 0.02 | F3: Main local light-feature anchor
A4: Iceland | B4: EuroNorth | C4: 38 | D4: Iceland 1.00 | E4: LOCAL_LOCAL 0.95, DOUBLE_SURNAME_LOCAL_LOCAL 0.03, COMPOUND_GIVEN_LOCAL_LOCAL 0.02 | F4: Secondary local north-atlantic read
A5: Iceland | B5: RedHair | C5: 4 | D5: Iceland 1.00 | E5: LOCAL_LOCAL 0.95, DOUBLE_SURNAME_LOCAL_LOCAL 0.03, COMPOUND_GIVEN_LOCAL_LOCAL 0.02 | F5: Small local ginger accent
A6: Norway | B6: Scandinavia | C6: 56 | D6: Norway 0.88, Denmark 0.07, Sweden 0.05 | E6: LOCAL_LOCAL 0.95, DOUBLE_SURNAME_LOCAL_LOCAL 0.03, COMPOUND_GIVEN_LOCAL_LOCAL 0.02 | F6: Main local light-feature anchor
A7: Norway | B7: EuroNorth | C7: 29 | D7: Norway 0.88, Denmark 0.07, Sweden 0.05 | E7: LOCAL_LOCAL 0.95, DOUBLE_SURNAME_LOCAL_LOCAL 0.03, COMPOUND_GIVEN_LOCAL_LOCAL 0.02 | F7: Secondary local north-atlantic read
A8: Norway | B8: Anatolian | C8: 3 | D8: Turkey 0.85, Norway 0.15 | E8: LOCAL_HERITAGE 0.42, HERITAGE_HERITAGE 0.53, LOCAL_LOCAL 0.04, HERITAGE_LOCAL 0.01 | F8: Separate Turkish row
A9: Norway | B9: Levant | C9: 5 | D9: Iraq 0.45, Syria 0.45, Lebanon 0.10 | E9: LOCAL_HERITAGE 0.42, HERITAGE_HERITAGE 0.53, LOCAL_LOCAL 0.04, HERITAGE_LOCAL 0.01 | F9: Iraq/Syria routed visually via Levant, naming stays country-based
A10: Norway | B10: Persia | C10: 2 | D10: Iran 0.90, Norway 0.10 | E10: LOCAL_HERITAGE 0.42, HERITAGE_HERITAGE 0.53, LOCAL_LOCAL 0.04, HERITAGE_LOCAL 0.01 | F10: Separate from Levant/Anatolian
A11: Norway | B11: AfricaHorn | C11: 2 | D11: Somalia 0.70, Ethiopia 0.30 | E11: LOCAL_HERITAGE 0.40, HERITAGE_HERITAGE 0.55, LOCAL_LOCAL 0.04, HERITAGE_LOCAL 0.01 | F11: Horn-heavy row; better than generic East Africa
A12: Norway | B12: RedHair | C12: 3 | D12: Norway 1.00 | E12: LOCAL_LOCAL 0.95, DOUBLE_SURNAME_LOCAL_LOCAL 0.03, COMPOUND_GIVEN_LOCAL_LOCAL 0.02 | F12: Small accent only
A13: Sweden | B13: Scandinavia | C13: 48 | D13: Sweden 0.92, Norway 0.08 | E13: LOCAL_LOCAL 0.95, DOUBLE_SURNAME_LOCAL_LOCAL 0.03, COMPOUND_GIVEN_LOCAL_LOCAL 0.02 | F13: Main local light-feature anchor
A14: Sweden | B14: EuroNorth | C14: 24 | D14: Sweden 0.92, Norway 0.08 | E14: LOCAL_LOCAL 0.95, DOUBLE_SURNAME_LOCAL_LOCAL 0.03, COMPOUND_GIVEN_LOCAL_LOCAL 0.02 | F14: Secondary local north-European read
... A360: Israel | B360: Levant | C360: 2 | D360: Israel Hebrew 0.55, Palestine 0.20, Lebanon 0.10, Syria 0.10, Jordan 0.05 | E360: LOCAL_HERITAGE 0.55, HERITAGE_HERITAGE 0.30, LOCAL_LOCAL 0.10, HERITAGE_LOCAL 0.05 | F360: Mixed local row

Sheet Sheet18
A3: Sum of Weight | B3: Column Labels
A4: Row Labels | B4: T1 | C4: T2 | D4: (blank) | E4: Grand Total
A5: Turkey | B5: 24.24 | C5: 12.8 | E5: 37.04
A6: Nigeria | B6: 20.92 | C6: 13.55 | E6: 34.47
A7: Brazil | B7: 14.34 | C7: 10.58 | E7: 24.92
A8: Ghana | B8: 15.15 | C8: 9.54 | E8: 24.69
A9: Senegal | B9: 12.24 | C9: 11.6 | E9: 23.84
A10: Spain | B10: 15 | C10: 7.78 | E10: 22.78
A11: Iran | B11: 13.4 | C11: 8.88 | E11: 22.28
A12: Egypt | B12: 12.76 | C12: 7.63 | E12: 20.39
A13: India South | B13: 11.27 | C13: 8.42 | E13: 19.69
A14: Mali | B14: 7.74 | C14: 10.09 | E14: 17.83
A15: Cameroon | B15: 5.74 | C15: 11.54 | E15: 17.28
A16: Colombia | B16: 10.64 | C16: 6.6 | E16: 17.24
... A80: Armenia | B80: 2.81 | C80: 2.63 | E80: 5.44
A81: Israel Hebrew | B81: 5.41 | E81: 5.41
A82: Sweden | B82: 5.4 | E82: 5.4
A83: Singapore Chinese | B83: 4.6 | C83: 0.75 | E83: 5.35
A84: Guinea | B84: 1.58 | C84: 3.76 | E84: 5.34
A85: China North | B85: 4.36 | C85: 0.9 | E85: 5.26
A86: Kosovo | B86: 2.84 | C86: 2.33 | E86: 5.17
A87: Fiji Indigenous | B87: 2.8 | C87: 2.3 | E87: 5.1
A88: Indonesia Other | B88: 2.09 | C88: 2.9 | E88: 4.99
A89: Guatemala | B89: 1.73 | C89: 3.26 | E89: 4.99
A90: Malaysia Malay | B90: 2.56 | C90: 2.4 | E90: 4.96
A91: Oman | B91: 2.4 | C91: 2.45 | E91: 4.85
A92: Bulgaria | B92: 3.74 | C92: 1.09 | E92: 4.83
A93: Hungary | B93: 4.55 | C93: 0.2 | E93: 4.75
A94: North Macedonia | B94: 1.98 | C94: 2.75 | E94: 4.73
... A97: South Africa | B97: 1.73 | C97: 2.91 | E97: 4.64
A98: Scotland | B98: 4.6 | E98: 4.6
A99: Greece | B99: 2.94 | C99: 1.63 | E99: 4.57
A100: Samoa | B100: 1.51 | C100: 2.92 | E100: 4.43
A101: Latvia | B101: 4.27 | C101: 0.15 | E101: 4.42
A102: India Punjabi | B102: 3.05 | C102: 1.35 | E102: 4.4
A103: Cape Verde | B103: 1.23 | C103: 3.15 | E103: 4.38
A104: Slovakia | B104: 4.21 | C104: 0.15 | E104: 4.36
A105: Philippines Visayan | B105: 4.33 | E105: 4.33
A106: Papua New Guinea | B106: 1.6 | C106: 2.72 | E106: 4.32
A107: Thailand | B107: 3.69 | C107: 0.61 | E107: 4.3
...

Sheet heritage_africa_arab
A1: Country | B1: VisualBucket | C1: percent | D1: naming pool | E1: naming split | F1: notes
A2: Morocco | B2: AfricaNorth Maghreb | C2: 88 | D2: Morocco 0.94, Algeria 0.04, Tunisia 0.02 | E2: LOCAL_LOCAL 0.95, DOUBLE_SURNAME_LOCAL_LOCAL 0.03, COMPOUND_GIVEN_LOCAL_LOCAL 0.02 | F2: Main local pool
A3: Morocco | B3: AfricaWest | C3: 6 | D3: Senegal 0.30, Mali 0.25, Guinea 0.25, Ivory Coast 0.20 | E3: LOCAL_HERITAGE 0.45, HERITAGE_HERITAGE 0.50, LOCAL_LOCAL 0.04, HERITAGE_LOCAL 0.01 | F3: Sahel/West African football adjacency without unsupported pools
A4: Morocco | B4: EuroIberian | C4: 4 | D4: Spain 0.60, Portugal 0.40 | E4: LOCAL_HERITAGE 0.48, HERITAGE_HERITAGE 0.45, LOCAL_LOCAL 0.05, HERITAGE_LOCAL 0.02 | F4: Iberian adjacency trace
A5: Morocco | B5: Egypt | C5: 2 | D5: Egypt 1.00 | E5: LOCAL_HERITAGE 0.45, HERITAGE_HERITAGE 0.50, LOCAL_LOCAL 0.04, HERITAGE_LOCAL 0.01 | F5: Small east-North-African bridge; cleaner than decorative AfricaSouth row
A6: Algeria | B6: AfricaNorth Maghreb | C6: 88 | D6: Algeria 0.94, Morocco 0.04, Tunisia 0.02 | E6: LOCAL_LOCAL 0.95, DOUBLE_SURNAME_LOCAL_LOCAL 0.03, COMPOUND_GIVEN_LOCAL_LOCAL 0.02 | F6: Main local pool
A7: Algeria | B7: AfricaWest | C7: 5 | D7: Mali 0.30, Senegal 0.25, Guinea 0.25, Ivory Coast 0.20 | E7: LOCAL_HERITAGE 0.45, HERITAGE_HERITAGE 0.50, LOCAL_LOCAL 0.04, HERITAGE_LOCAL 0.01 | F7: Sahel adjacency using supported pools only
A8: Algeria | B8: Levant | C8: 3 | D8: Syria 0.35, Lebanon 0.25, Palestine 0.20, Iraq 0.20 | E8: LOCAL_HERITAGE 0.42, HERITAGE_HERITAGE 0.53, LOCAL_LOCAL 0.04, HERITAGE_LOCAL 0.01 | F8: Small West Asian spill
A9: Algeria | B9: EuroIberian | C9: 2 | D9: Spain 0.65, France 0.35 | E9: LOCAL_HERITAGE 0.48, HERITAGE_HERITAGE 0.45, LOCAL_LOCAL 0.05, HERITAGE_LOCAL 0.02 | F9: Mediterranean adjacency
A10: Algeria | B10: Egypt | C10: 2 | D10: Egypt 1.00 | E10: LOCAL_HERITAGE 0.45, HERITAGE_HERITAGE 0.50, LOCAL_LOCAL 0.04, HERITAGE_LOCAL 0.01 | F10: Interior/eastward bridge without unsupported Sahel pools
A11: Tunisia | B11: AfricaNorth Maghreb | C11: 88 | D11: Tunisia 0.90, Algeria 0.05, Libya 0.03, Morocco 0.02 | E11: LOCAL_LOCAL 0.95, DOUBLE_SURNAME_LOCAL_LOCAL 0.03, COMPOUND_GIVEN_LOCAL_LOCAL 0.02 | F11: Main local pool
A12: Tunisia | B12: Levant | C12: 4 | D12: Lebanon 0.30, Syria 0.25, Palestine 0.25, Iraq 0.20 | E12: LOCAL_HERITAGE 0.42, HERITAGE_HERITAGE 0.53, LOCAL_LOCAL 0.04, HERITAGE_LOCAL 0.01 | F12: Eastward Mediterranean spill
A13: Tunisia | B13: AfricaWest | C13: 4 | D13: Mali 0.30, Senegal 0.25, Guinea 0.25, Ivory Coast 0.20 | E13: LOCAL_HERITAGE 0.45, HERITAGE_HERITAGE 0.50, LOCAL_LOCAL 0.04, HERITAGE_LOCAL 0.01 | F13: Sahel adjacency using supported pools
... A324: Chad | B324: AfricaSahelia | C324: 2 | D324: Sudan 0.35, Cameroon 0.25, Nigeria 0.20, Mali 0.20 | E324: LOCAL_HERITAGE 0.55, HERITAGE_HERITAGE 0.30, LOCAL_LOCAL 0.10, HERITAGE_LOCAL 0.05 | F324: Mixed Sahel-central row

Sheet heritage_asia
A1: Country | B1: VisualBucket | C1: percent | D1: naming pool | E1: naming split | F1: notes
A2: India | B2: IndiaGangetic | C2: 32 | D2: India Gangetic 0.78, India Punjabi 0.10, India Bengali 0.07, India South 0.05 | E2: LOCAL_LOCAL 0.95, DOUBLE_SURNAME_LOCAL_LOCAL 0.03, COMPOUND_GIVEN_LOCAL_LOCAL 0.02 | F2: Main north/central anchor
A3: India | B3: IndiaSouth | C3: 26 | D3: India South 0.88, India Gangetic 0.07, India Bengali 0.03, India Punjabi 0.02 | E3: LOCAL_LOCAL 0.95, DOUBLE_SURNAME_LOCAL_LOCAL 0.03, COMPOUND_GIVEN_LOCAL_LOCAL 0.02 | F3: Main south anchor
A4: India | B4: IndiaPunjab | C4: 18 | D4: India Punjabi 0.88, India Gangetic 0.08, Pakistan Punjabi 0.04 | E4: LOCAL_LOCAL 0.95, DOUBLE_SURNAME_LOCAL_LOCAL 0.03, COMPOUND_GIVEN_LOCAL_LOCAL 0.02 | F4: Main northwestern anchor
A5: India | B5: IndiaBengali | C5: 12 | D5: India Bengali 0.82, Bangladesh 0.12, India Gangetic 0.06 | E5: LOCAL_LOCAL 0.95, DOUBLE_SURNAME_LOCAL_LOCAL 0.03, COMPOUND_GIVEN_LOCAL_LOCAL 0.02 | F5: Main eastern anchor
A6: India | B6: IndieSriLanka | C6: 2 | D6: Sri Lanka Tamil 0.70, India South 0.30 | E6: LOCAL_HERITAGE 0.48, HERITAGE_HERITAGE 0.45, LOCAL_LOCAL 0.05, HERITAGE_LOCAL 0.02 | F6: South Indian/Tamil bridge
A7: India | B7: Persia | C7: 2 | D7: Afghanistan Dari 0.55, Iran 0.45 | E7: LOCAL_HERITAGE 0.44, HERITAGE_HERITAGE 0.51, LOCAL_LOCAL 0.04, HERITAGE_LOCAL 0.01 | F7: Northwest bridge
A8: India | B8: ArabPeninsula | C8: 2 | D8: Saudi Arabia 0.40, UAE 0.25, Oman 0.20, Kuwait 0.15 | E8: LOCAL_HERITAGE 0.44, HERITAGE_HERITAGE 0.51, LOCAL_LOCAL 0.04, HERITAGE_LOCAL 0.01 | F8: Gulf-facing spill
A9: India | B9: AfricaEast | C9: 2 | D9: Kenya 0.40, Tanzania 0.35, Uganda 0.25 | E9: LOCAL_HERITAGE 0.42, HERITAGE_HERITAGE 0.53, LOCAL_LOCAL 0.04, HERITAGE_LOCAL 0.01 | F9: Indian Ocean spill
A10: India | B10: IndiaSouth | C10: 4 | D10: India South 0.55, India Gangetic 0.20, India Punjabi 0.15, India Bengali 0.10 | E10: LOCAL_HERITAGE 0.55, HERITAGE_HERITAGE 0.30, LOCAL_LOCAL 0.10, HERITAGE_LOCAL 0.05 | F10: Mixed pan-Indian modern row
A11: Pakistan | B11: IndiaPunjab | C11: 48 | D11: Pakistan Punjabi 0.82, India Punjabi 0.10, Pakistan Sindhi 0.08 | E11: LOCAL_LOCAL 0.95, DOUBLE_SURNAME_LOCAL_LOCAL 0.03, COMPOUND_GIVEN_LOCAL_LOCAL 0.02 | F11: Main local anchor
A12: Pakistan | B12: Persia | C12: 16 | D12: Afghanistan Dari 0.50, Iran 0.35, Pakistan Pashtun 0.15 | E12: LOCAL_HERITAGE 0.44, HERITAGE_HERITAGE 0.51, LOCAL_LOCAL 0.04, HERITAGE_LOCAL 0.01 | F12: Western/Iranian-family spill
A13: Pakistan | B13: IndiaGangetic | C13: 8 | D13: Pakistan Punjabi 0.45, India Gangetic 0.35, Pakistan Sindhi 0.20 | E13: LOCAL_HERITAGE 0.45, HERITAGE_HERITAGE 0.50, LOCAL_LOCAL 0.04, HERITAGE_LOCAL 0.01 | F13: Broad north-plain bridge
... A197: Singapore | B197: Korea | C197: 2 | D197: Korea 1.00 | E197: LOCAL_HERITAGE 0.44, HERITAGE_HERITAGE 0.51, LOCAL_LOCAL 0.04, HERITAGE_LOCAL 0.01 | F197: Small spill

Sheet heritage_Latin_Caribbean
A1: Country | B1: VisualBucket | C1: percent | D1: naming pool | E1: naming split | F1: notes
A2: Mexico | B2: MesoAmericaMestizo | C2: 62 | D2: Mexico 0.88, Guatemala 0.06, Honduras 0.03, El Salvador 0.03 | E2: LOCAL_LOCAL 0.95, DOUBLE_SURNAME_LOCAL_LOCAL 0.03, COMPOUND_GIVEN_LOCAL_LOCAL 0.02 | F2: Main local anchor
A3: Mexico | B3: MesoAmericaIndigenous | C3: 20 | D3: Mexico 0.78, Guatemala 0.12, Bolivia 0.05, Peru 0.05 | E3: LOCAL_LOCAL 0.90, DOUBLE_SURNAME_LOCAL_LOCAL 0.05, COMPOUND_GIVEN_LOCAL_LOCAL 0.05 | F3: Indigenous-leaning local read
A4: Mexico | B4: SouthAmericaNorth | C4: 5 | D4: Colombia 0.35, Venezuela 0.30, Ecuador 0.20, Dominican Republic 0.15 | E4: LOCAL_HERITAGE 0.42, HERITAGE_HERITAGE 0.53, LOCAL_LOCAL 0.04, HERITAGE_LOCAL 0.01 | F4: Pan-Latin spill
A5: Mexico | B5: AfroCaribbean | C5: 4 | D5: Cuba 0.35, Dominican Republic 0.35, Jamaica 0.30 | E5: LOCAL_HERITAGE 0.42, HERITAGE_HERITAGE 0.53, LOCAL_LOCAL 0.04, HERITAGE_LOCAL 0.01 | F5: Caribbean spill without unsupported Puerto Rico
A6: Mexico | B6: Andean | C6: 4 | D6: Peru 0.35, Ecuador 0.30, Bolivia 0.20, Colombia 0.15 | E6: LOCAL_HERITAGE 0.42, HERITAGE_HERITAGE 0.53, LOCAL_LOCAL 0.04, HERITAGE_LOCAL 0.01 | F6: Southward spill
A7: Mexico | B7: EuroIberian | C7: 3 | D7: Spain 0.75, Portugal 0.25 | E7: LOCAL_HERITAGE 0.48, HERITAGE_HERITAGE 0.45, LOCAL_LOCAL 0.05, HERITAGE_LOCAL 0.02 | F7: Iberian spill
A8: Mexico | B8: AfricaWest | C8: 2 | D8: Nigeria 0.35, Ghana 0.25, Senegal 0.20, Ivory Coast 0.20 | E8: LOCAL_HERITAGE 0.38, HERITAGE_HERITAGE 0.57, LOCAL_LOCAL 0.04, HERITAGE_LOCAL 0.01 | F8: Small football spill
A9: Guatemala | B9: MesoAmericaMestizo | C9: 46 | D9: Guatemala 0.68, Mexico 0.18, Honduras 0.08, El Salvador 0.06 | E9: LOCAL_LOCAL 0.95, DOUBLE_SURNAME_LOCAL_LOCAL 0.03, COMPOUND_GIVEN_LOCAL_LOCAL 0.02 | F9: Main local mestizo-facing anchor
A10: Guatemala | B10: MesoAmericaIndigenous | C10: 36 | D10: Guatemala 0.76, Mexico 0.16, Bolivia 0.08 | E10: LOCAL_LOCAL 0.95, DOUBLE_SURNAME_LOCAL_LOCAL 0.03, COMPOUND_GIVEN_LOCAL_LOCAL 0.02 | F10: Main local indigenous-facing anchor
A11: Guatemala | B11: SouthAmericaNorth | C11: 4 | D11: Colombia 0.35, Venezuela 0.30, Ecuador 0.20, Dominican Republic 0.15 | E11: LOCAL_HERITAGE 0.42, HERITAGE_HERITAGE 0.53, LOCAL_LOCAL 0.04, HERITAGE_LOCAL 0.01 | F11: Latin spill
A12: Guatemala | B12: AfroCaribbean | C12: 4 | D12: Cuba 0.35, Dominican Republic 0.35, Jamaica 0.30 | E12: LOCAL_HERITAGE 0.42, HERITAGE_HERITAGE 0.53, LOCAL_LOCAL 0.04, HERITAGE_LOCAL 0.01 | F12: Caribbean spill without unsupported Puerto Rico
A13: Guatemala | B13: Andean | C13: 4 | D13: Peru 0.35, Ecuador 0.30, Bolivia 0.20, Colombia 0.15 | E13: LOCAL_HERITAGE 0.42, HERITAGE_HERITAGE 0.53, LOCAL_LOCAL 0.04, HERITAGE_LOCAL 0.01 | F13: Southward spill
... A218: Aruba | B218: AfroCaribbean | C218: 2 | D218: Netherlands 0.20, Dominican Republic 0.20, Venezuela 0.20, Colombia 0.20, Brazil 0.20 | E218: LOCAL_HERITAGE 0.55, HERITAGE_HERITAGE 0.30, LOCAL_LOCAL 0.10, HERITAGE_LOCAL 0.05 | F218: Mixed proxy row

Sheet heritage_oceania
A1: Country | B1: VisualBucket | C1: percent | D1: naming pool | E1: naming split | F1: notes
A2: Australia | B2: BritishIsles | C2: 58 | D2: England 0.48, Scotland 0.16, Ireland 0.14, Wales 0.10, Australia 0.12 | E2: LOCAL_LOCAL 0.95, DOUBLE_SURNAME_LOCAL_LOCAL 0.03, COMPOUND_GIVEN_LOCAL_LOCAL 0.02 | F2: Main local anchor
A3: Australia | B3: EuroNorth | C3: 8 | D3: England 0.35, Scotland 0.20, Ireland 0.20, New Zealand 0.25 | E3: LOCAL_LOCAL 0.90, DOUBLE_SURNAME_LOCAL_LOCAL 0.05, COMPOUND_GIVEN_LOCAL_LOCAL 0.05 | F3: Local lighter-feature spill
A4: Australia | B4: Philipines | C4: 3 | D4: Philippines Tagalog 1.00 | E4: LOCAL_HERITAGE 0.42, HERITAGE_HERITAGE 0.53, LOCAL_LOCAL 0.04, HERITAGE_LOCAL 0.01 | F4: Distinct Filipino spill
A5: Australia | B5: SEA insular | C5: 3 | D5: Malaysia Malay 0.28, Malaysia Chinese 0.22, Singapore Chinese 0.20, Indonesia Javanese 0.15, Indonesia Other 0.15 | E5: LOCAL_HERITAGE 0.42, HERITAGE_HERITAGE 0.53, LOCAL_LOCAL 0.04, HERITAGE_LOCAL 0.01 | F5: Maritime/island Southeast Asian spill
A6: Australia | B6: SEA Vietic | C6: 1 | D6: Vietnam 0.70, Singapore Chinese 0.15, Malaysia Chinese 0.15 | E6: LOCAL_HERITAGE 0.42, HERITAGE_HERITAGE 0.53, LOCAL_LOCAL 0.04, HERITAGE_LOCAL 0.01 | F6: Smaller Vietic spill
A7: Australia | B7: SEA Mekong | C7: 2 | D7: Thailand 0.40, Cambodia 0.30, Laos 0.30 | E7: LOCAL_HERITAGE 0.42, HERITAGE_HERITAGE 0.53, LOCAL_LOCAL 0.04, HERITAGE_LOCAL 0.01 | F7: Mekong spill
A8: Australia | B8: IndiaSouth | C8: 4 | D8: India South 0.45, India Gangetic 0.20, Pakistan Punjabi 0.20, Bangladesh 0.15 | E8: LOCAL_HERITAGE 0.42, HERITAGE_HERITAGE 0.53, LOCAL_LOCAL 0.04, HERITAGE_LOCAL 0.01 | F8: South Asian spill
A9: Australia | B9: AfricaWest | C9: 3 | D9: Nigeria 0.35, Ghana 0.25, Senegal 0.20, Ivory Coast 0.20 | E9: LOCAL_HERITAGE 0.38, HERITAGE_HERITAGE 0.57, LOCAL_LOCAL 0.04, HERITAGE_LOCAL 0.01 | F9: Football spill
A10: Australia | B10: Polynesia | C10: 7 | D10: New Zealand Māori 0.35, Samoa 0.25, Tonga 0.20, Fiji Indigenous 0.20 | E10: LOCAL_HERITAGE 0.44, HERITAGE_HERITAGE 0.51, LOCAL_LOCAL 0.04, HERITAGE_LOCAL 0.01 | F10: Oceania spill
A11: Australia | B11: Melanesia | C11: 4 | D11: Papua New Guinea 0.35, Solomon Islands 0.25, Vanuatu 0.20, Fiji Indigenous 0.20 | E11: LOCAL_HERITAGE 0.44, HERITAGE_HERITAGE 0.51, LOCAL_LOCAL 0.04, HERITAGE_LOCAL 0.01 | F11: Melanesian spill
A12: Australia | B12: BritishIsles | C12: 7 | D12: England 0.40, Scotland 0.18, Ireland 0.14, Wales 0.08, Australia 0.20 | E12: LOCAL_HERITAGE 0.55, HERITAGE_HERITAGE 0.30, LOCAL_LOCAL 0.10, HERITAGE_LOCAL 0.05 | F12: Mixed Australian row
A13: New Zealand | B13: BritishIsles | C13: 44 | D13: England 0.40, Scotland 0.18, Ireland 0.16, Wales 0.10, New Zealand 0.16 | E13: LOCAL_LOCAL 0.95, DOUBLE_SURNAME_LOCAL_LOCAL 0.03, COMPOUND_GIVEN_LOCAL_LOCAL 0.02 | F13: Main local anchor
... A69: New Caledonia | B69: Melanesia | C69: 10 | D69: New Caledonia 0.35, Vanuatu 0.20, Solomon Islands 0.15, Papua New Guinea 0.10, France 0.20 | E69: LOCAL_HERITAGE 0.55, HERITAGE_HERITAGE 0.30, LOCAL_LOCAL 0.10, HERITAGE_LOCAL 0.05 | F69: Mixed local row

Sheet heritage_america
A1: Country | B1: VisualBucket | C1: percent | D1: naming pool | E1: naming split | F1: notes
A2: United States | B2: EuroNorth | C2: 18 | D2: United States 0.45, Germany 0.20, Netherlands 0.10, Norway 0.10, Sweden 0.10, Denmark 0.05 | E2: LOCAL_LOCAL 0.95, DOUBLE_SURNAME_LOCAL_LOCAL 0.03, COMPOUND_GIVEN_LOCAL_LOCAL 0.02 | F2: Broad lighter-feature white local anchor
A3: United States | B3: BritishIsles | C3: 16 | D3: United States 0.42, England 0.26, Ireland 0.16, Scotland 0.10, Wales 0.06 | E3: LOCAL_LOCAL 0.95, DOUBLE_SURNAME_LOCAL_LOCAL 0.03, COMPOUND_GIVEN_LOCAL_LOCAL 0.02 | F3: Anglo-Celtic local anchor
A4: United States | B4: EuroCentral | C4: 10 | D4: United States 0.40, Germany 0.24, Italy 0.10, France 0.10, Poland 0.08, Austria 0.08 | E4: LOCAL_LOCAL 0.95, DOUBLE_SURNAME_LOCAL_LOCAL 0.03, COMPOUND_GIVEN_LOCAL_LOCAL 0.02 | F4: Broad continental white anchor
A5: United States | B5: AfricaWest | C5: 13 | D5: United States 0.40, Nigeria 0.20, Ghana 0.15, Jamaica 0.15, Senegal 0.10 | E5: LOCAL_LOCAL 0.90, DOUBLE_SURNAME_LOCAL_LOCAL 0.05, COMPOUND_GIVEN_LOCAL_LOCAL 0.05 | F5: Major football-use Black American anchor; naming kept broad US-local
A6: United States | B6: AfroCaribbean | C6: 5 | D6: Jamaica 0.32, Haiti 0.20, Trinidad and Tobago 0.20, Dominican Republic 0.16, Cuba 0.12 | E6: LOCAL_HERITAGE 0.46, HERITAGE_HERITAGE 0.49, LOCAL_LOCAL 0.04, HERITAGE_LOCAL 0.01 | F6: Caribbean black/mixed spill; removed unsupported Puerto Rico
A7: United States | B7: MesoAmericaMestizo | C7: 16 | D7: Mexico 0.52, El Salvador 0.14, Guatemala 0.10, Honduras 0.10, Dominican Republic 0.08, United States 0.06 | E7: LOCAL_LOCAL 0.90, DOUBLE_SURNAME_LOCAL_LOCAL 0.05, COMPOUND_GIVEN_LOCAL_LOCAL 0.05 | F7: Major Hispanic football anchor; naming kept broad US-local
A8: United States | B8: SouthAmericaNorth | C8: 6 | D8: Colombia 0.32, Venezuela 0.24, Ecuador 0.16, Peru 0.12, Dominican Republic 0.10, United States 0.06 | E8: LOCAL_HERITAGE 0.44, HERITAGE_HERITAGE 0.51, LOCAL_LOCAL 0.04, HERITAGE_LOCAL 0.01 | F8: Pan-Latin spill
A9: United States | B9: IndiaSouth | C9: 3 | D9: India South 0.36, India Gangetic 0.22, Pakistan Punjabi 0.18, Bangladesh 0.12, United States 0.12 | E9: LOCAL_HERITAGE 0.40, HERITAGE_HERITAGE 0.55, LOCAL_LOCAL 0.04, HERITAGE_LOCAL 0.01 | F9: South Asian spill; naming kept broad US-local
A10: United States | B10: Levant | C10: 2 | D10: Lebanon 0.30, Syria 0.20, Palestine 0.20, Iraq 0.15, Jordan 0.15 | E10: LOCAL_HERITAGE 0.42, HERITAGE_HERITAGE 0.53, LOCAL_LOCAL 0.04, HERITAGE_LOCAL 0.01 | F10: Arab-American spill
A11: United States | B11: China | C11: 2 | D11: China 0.70, Taiwan 0.15, United States 0.15 | E11: LOCAL_HERITAGE 0.40, HERITAGE_HERITAGE 0.55, LOCAL_LOCAL 0.04, HERITAGE_LOCAL 0.01 | F11: East Asian spill; removed China North/South custom split
A12: United States | B12: Polynesia | C12: 2 | D12: Samoa 0.34, Tonga 0.24, Fiji 0.18, New Zealand 0.12, United States 0.12 | E12: LOCAL_HERITAGE 0.44, HERITAGE_HERITAGE 0.51, LOCAL_LOCAL 0.04, HERITAGE_LOCAL 0.01 | F12: Pacific/Island spill; removed Hawaii and Māori custom pools
A13: United States | B13: RedHair | C13: 2 | D13: United States 0.50, Ireland 0.25, Scotland 0.15, England 0.10 | E13: LOCAL_LOCAL 0.95, DOUBLE_SURNAME_LOCAL_LOCAL 0.03, COMPOUND_GIVEN_LOCAL_LOCAL 0.02 | F13: Optional ginger injection, naming stays local
... A30: Canada | B30: BritishIsles | C30: 5 | D30: Canada 0.44, England 0.18, France 0.10, Nigeria 0.08, Jamaica 0.08, India South 0.06, Lebanon 0.03, China 0.03 | E30: LOCAL_HERITAGE 0.55, HERITAGE_HERITAGE 0.30, LOCAL_LOCAL 0.10, HERITAGE_LOCAL 0.05 | F30: Mixed modern Canadian row
